Creating test database for alias 'default'...
EEE......
======================================================================
ERROR: test_a1 (content_display.tests.ActivityTest)
----------------------------------------------------------------------
Traceback (most recent call last):
  File "/v/filer4b/v38q001/jpm2873/Documents/cs373se/cs373-idb/ITDb/content_display/tests.py", line 47, in setUp
    Activities.objects.create(name = 'Shark Diving', type_activity = 'Outdoor Recreation', pictures = '1')
  File "/usr/local/lib/python2.7/dist-packages/django/db/models/manager.py", line 157, in create
    return self.get_queryset().create(**kwargs)
  File "/usr/local/lib/python2.7/dist-packages/django/db/models/query.py", line 319, in create
    obj.save(force_insert=True, using=self.db)
  File "/usr/local/lib/python2.7/dist-packages/django/db/models/base.py", line 545, in save
    force_update=force_update, update_fields=update_fields)
  File "/usr/local/lib/python2.7/dist-packages/django/db/models/base.py", line 573, in save_base
    updated = self._save_table(raw, cls, force_insert, force_update, using, update_fields)
  File "/usr/local/lib/python2.7/dist-packages/django/db/models/base.py", line 654, in _save_table
    result = self._do_insert(cls._base_manager, using, fields, update_pk, raw)
  File "/usr/local/lib/python2.7/dist-packages/django/db/models/base.py", line 687, in _do_insert
    using=using, raw=raw)
  File "/usr/local/lib/python2.7/dist-packages/django/db/models/manager.py", line 232, in _insert
    return insert_query(self.model, objs, fields, **kwargs)
  File "/usr/local/lib/python2.7/dist-packages/django/db/models/query.py", line 1511, in insert_query
    return query.get_compiler(using=using).execute_sql(return_id)
  File "/usr/local/lib/python2.7/dist-packages/django/db/models/sql/compiler.py", line 899, in execute_sql
    cursor.execute(sql, params)
  File "/usr/local/lib/python2.7/dist-packages/django/db/backends/util.py", line 53, in execute
    return self.cursor.execute(sql, params)
  File "/usr/local/lib/python2.7/dist-packages/django/db/utils.py", line 99, in __exit__
    six.reraise(dj_exc_type, dj_exc_value, traceback)
  File "/usr/local/lib/python2.7/dist-packages/django/db/backends/util.py", line 53, in execute
    return self.cursor.execute(sql, params)
  File "/usr/local/lib/python2.7/dist-packages/django/db/backends/sqlite3/base.py", line 450, in execute
    return Database.Cursor.execute(self, query, params)
IntegrityError: content_display_activities.city_id may not be NULL

======================================================================
ERROR: test_a2 (content_display.tests.ActivityTest)
----------------------------------------------------------------------
Traceback (most recent call last):
  File "/v/filer4b/v38q001/jpm2873/Documents/cs373se/cs373-idb/ITDb/content_display/tests.py", line 47, in setUp
    Activities.objects.create(name = 'Shark Diving', type_activity = 'Outdoor Recreation', pictures = '1')
  File "/usr/local/lib/python2.7/dist-packages/django/db/models/manager.py", line 157, in create
    return self.get_queryset().create(**kwargs)
  File "/usr/local/lib/python2.7/dist-packages/django/db/models/query.py", line 319, in create
    obj.save(force_insert=True, using=self.db)
  File "/usr/local/lib/python2.7/dist-packages/django/db/models/base.py", line 545, in save
    force_update=force_update, update_fields=update_fields)
  File "/usr/local/lib/python2.7/dist-packages/django/db/models/base.py", line 573, in save_base
    updated = self._save_table(raw, cls, force_insert, force_update, using, update_fields)
  File "/usr/local/lib/python2.7/dist-packages/django/db/models/base.py", line 654, in _save_table
    result = self._do_insert(cls._base_manager, using, fields, update_pk, raw)
  File "/usr/local/lib/python2.7/dist-packages/django/db/models/base.py", line 687, in _do_insert
    using=using, raw=raw)
  File "/usr/local/lib/python2.7/dist-packages/django/db/models/manager.py", line 232, in _insert
    return insert_query(self.model, objs, fields, **kwargs)
  File "/usr/local/lib/python2.7/dist-packages/django/db/models/query.py", line 1511, in insert_query
    return query.get_compiler(using=using).execute_sql(return_id)
  File "/usr/local/lib/python2.7/dist-packages/django/db/models/sql/compiler.py", line 899, in execute_sql
    cursor.execute(sql, params)
  File "/usr/local/lib/python2.7/dist-packages/django/db/backends/util.py", line 53, in execute
    return self.cursor.execute(sql, params)
  File "/usr/local/lib/python2.7/dist-packages/django/db/utils.py", line 99, in __exit__
    six.reraise(dj_exc_type, dj_exc_value, traceback)
  File "/usr/local/lib/python2.7/dist-packages/django/db/backends/util.py", line 53, in execute
    return self.cursor.execute(sql, params)
  File "/usr/local/lib/python2.7/dist-packages/django/db/backends/sqlite3/base.py", line 450, in execute
    return Database.Cursor.execute(self, query, params)
IntegrityError: content_display_activities.city_id may not be NULL

======================================================================
ERROR: test_a3 (content_display.tests.ActivityTest)
----------------------------------------------------------------------
Traceback (most recent call last):
  File "/v/filer4b/v38q001/jpm2873/Documents/cs373se/cs373-idb/ITDb/content_display/tests.py", line 47, in setUp
    Activities.objects.create(name = 'Shark Diving', type_activity = 'Outdoor Recreation', pictures = '1')
  File "/usr/local/lib/python2.7/dist-packages/django/db/models/manager.py", line 157, in create
    return self.get_queryset().create(**kwargs)
  File "/usr/local/lib/python2.7/dist-packages/django/db/models/query.py", line 319, in create
    obj.save(force_insert=True, using=self.db)
  File "/usr/local/lib/python2.7/dist-packages/django/db/models/base.py", line 545, in save
    force_update=force_update, update_fields=update_fields)
  File "/usr/local/lib/python2.7/dist-packages/django/db/models/base.py", line 573, in save_base
    updated = self._save_table(raw, cls, force_insert, force_update, using, update_fields)
  File "/usr/local/lib/python2.7/dist-packages/django/db/models/base.py", line 654, in _save_table
    result = self._do_insert(cls._base_manager, using, fields, update_pk, raw)
  File "/usr/local/lib/python2.7/dist-packages/django/db/models/base.py", line 687, in _do_insert
    using=using, raw=raw)
  File "/usr/local/lib/python2.7/dist-packages/django/db/models/manager.py", line 232, in _insert
    return insert_query(self.model, objs, fields, **kwargs)
  File "/usr/local/lib/python2.7/dist-packages/django/db/models/query.py", line 1511, in insert_query
    return query.get_compiler(using=using).execute_sql(return_id)
  File "/usr/local/lib/python2.7/dist-packages/django/db/models/sql/compiler.py", line 899, in execute_sql
    cursor.execute(sql, params)
  File "/usr/local/lib/python2.7/dist-packages/django/db/backends/util.py", line 53, in execute
    return self.cursor.execute(sql, params)
  File "/usr/local/lib/python2.7/dist-packages/django/db/utils.py", line 99, in __exit__
    six.reraise(dj_exc_type, dj_exc_value, traceback)
  File "/usr/local/lib/python2.7/dist-packages/django/db/backends/util.py", line 53, in execute
    return self.cursor.execute(sql, params)
  File "/usr/local/lib/python2.7/dist-packages/django/db/backends/sqlite3/base.py", line 450, in execute
    return Database.Cursor.execute(self, query, params)
IntegrityError: content_display_activities.city_id may not be NULL

----------------------------------------------------------------------
Ran 9 tests in 0.018s

FAILED (errors=3)
Destroying test database for alias 'default'...
